"""Иногда это совсем не то, что нам требуется. Например, серверные программы
обычно должны оставаться активными даже после появления внутренних
ошибок. Если вам требуется избежать реакции на исключение по умолчанию,
достаточно просто перехватить исключение, обернув вызов функции инструк-
цией try:"""
try:
    a=[1,2,3]
    print(a[35])
except IndexError:
    print("Index out of range", IndexError)

